Workbook

Sheet Maintenance
A1: Item no | B1: New Item Description | C1: New Item Group | D1: Item Cost | E1: New Inventory | F1: In Stock | G1: Total Cost | H1: Department | I1: Category | J1: Machine | K1: Product Nature | L1: Category2 | M1: Seq | N1: New Item Code | O1: len | P1: Item Group | Q1: Item Group Name | R1: Product group | S1: Product group Description | T1: Column1
A2: ABB-0001 | B2: Package wires on the robot - signal 25463 - ROBOFLEX 2001 12G0,5 QMM 300/500V, | C2: Critical Spares-CS | D2: 84.214 | E2: Yes | F2: 20 | G2: =Table4[[#This Row],[Item Cost]]*Table4[[#This Row],[In Stock]] -> 1684.28 | H2: Spare Parts | I2: Critical Spares | J2: ABB | K2: wires | L2: Common | M2: =IF(LEN(COUNTIFS($H$1:H2,$H2,$I$1:I2,$I2,$J$1:J2,$J2,$K$1:K2,K2,$L$1:L2,L2))=1,"00"&COUNTIFS($H$1:H2,$H2,$I$1:I2,$I2,$J$1:J2,$J2,$K$1:K2,K2,$L$1:L2,L2),IF(LEN(COUNTIFS($H$1:H2,$H2,$I$1:I2,$I2,$J$1:J2,$J2,$K$1:K2,K2,$L$1:L2,L2))=2,"0"&COUNTIFS($H$1:H2,$H2,$I$1:I2,$I2,$J$1:J2,$J2,$K$1:K2,K2,$L$1:L2,L2),COUNTIFS($H$1:H2,$H2,$I$1:I2,$I2,$J$1:J2,$J2,$K$1:K2,K2,$L$1:L2,L2))) -> 001 | N2: =VLOOKUP(Table4[[#This Row],[Department]],'Mapping code'!A:B,2,0)&"-"&VLOOKUP(Table4[[#This Row],[Category]],'Mapping code'!E:F,2,0)&"-"&VLOOKUP(Table4[[#This Row],[Machine]],'Mapping code'!I:J,2,0)&"-"&VLOOKUP(Table4[[#This Row],[Product Nature]],'Mapping code'!N:O,2,0)&"-"&VLOOKUP(Table4[[#This Row],[Category2]],'Mapping code'!Q:R,2,0)&"-"&Table4[[#This Row],[Seq]] -> #N/A | O2: =+LEN(Table4[[#This Row],[New Item Code]]) -> #N/A | P2: MP0100 | Q2: Spare parts | S2: Spare parts ABB | T2: ABB
A3: ABB-0002 | B3: Package wires on the robot - power supply 29692 - ÖLFLEX® ROBOT F1 ( C ) 4 G 2,5 + (2 x 1,0 | C3: Critical Spares-CS | D3: 76.194 | E3: Yes | F3: 20 | G3: =Table4[[#This Row],[Item Cost]]*Table4[[#This Row],[In Stock]] -> 1523.88 | H3: Spare Parts | I3: Critical Spares | J3: ABB | K3: wires | L3: Common | M3: =IF(LEN(COUNTIFS($H$1:H3,$H3,$I$1:I3,$I3,$J$1:J3,$J3,$K$1:K3,K3,$L$1:L3,L3))=1,"00"&COUNTIFS($H$1:H3,$H3,$I$1:I3,$I3,$J$1:J3,$J3,$K$1:K3,K3,$L$1:L3,L3),IF(LEN(COUNTIFS($H$1:H3,$H3,$I$1:I3,$I3,$J$1:J3,$J3,$K$1:K3,K3,$L$1:L3,L3))=2,"0"&COUNTIFS($H$1:H3,$H3,$I$1:I3,$I3,$J$1:J3,$J3,$K$1:K3,K3,$L$1:L3,L3),COUNTIFS($H$1:H3,$H3,$I$1:I3,$I3,$J$1:J3,$J3,$K$1:K3,K3,$L$1:L3,L3))) -> 002 | N3: =VLOOKUP(Table4[[#This Row],[Department]],'Mapping code'!A:B,2,0)&"-"&VLOOKUP(Table4[[#This Row],[Category]],'Mapping code'!E:F,2,0)&"-"&VLOOKUP(Table4[[#This Row],[Machine]],'Mapping code'!I:J,2,0)&"-"&VLOOKUP(Table4[[#This Row],[Product Nature]],'Mapping code'!N:O,2,0)&"-"&VLOOKUP(Table4[[#This Row],[Category2]],'Mapping code'!Q:R,2,0)&"-"&Table4[[#This Row],[Seq]] -> #N/A | O3: =+LEN(Table4[[#This Row],[New Item Code]]) -> #N/A | P3: MP0100 | Q3: Spare parts | S3: Spare parts ABB | T3: ABB
A4: ABB-0003 | B4: Electrospindle ES350L - H6161H0485 - New | C4: Critical Spares-CS | D4: 33284.66 | E4: Yes | F4: 1 | G4: =Table4[[#This Row],[Item Cost]]*Table4[[#This Row],[In Stock]] -> 33284.66 | H4: Spare Parts | I4: Critical Spares | J4: ABB | K4: Spindle | L4: Common | M4: =IF(LEN(COUNTIFS($H$1:H4,$H4,$I$1:I4,$I4,$J$1:J4,$J4,$K$1:K4,K4,$L$1:L4,L4))=1,"00"&COUNTIFS($H$1:H4,$H4,$I$1:I4,$I4,$J$1:J4,$J4,$K$1:K4,K4,$L$1:L4,L4),IF(LEN(COUNTIFS($H$1:H4,$H4,$I$1:I4,$I4,$J$1:J4,$J4,$K$1:K4,K4,$L$1:L4,L4))=2,"0"&COUNTIFS($H$1:H4,$H4,$I$1:I4,$I4,$J$1:J4,$J4,$K$1:K4,K4,$L$1:L4,L4),COUNTIFS($H$1:H4,$H4,$I$1:I4,$I4,$J$1:J4,$J4,$K$1:K4,K4,$L$1:L4,L4))) -> 001 | N4: =VLOOKUP(Table4[[#This Row],[Department]],'Mapping code'!A:B,2,0)&"-"&VLOOKUP(Table4[[#This Row],[Category]],'Mapping code'!E:F,2,0)&"-"&VLOOKUP(Table4[[#This Row],[Machine]],'Mapping code'!I:J,2,0)&"-"&VLOOKUP(Table4[[#This Row],[Product Nature]],'Mapping code'!N:O,2,0)&"-"&VLOOKUP(Table4[[#This Row],[Category2]],'Mapping code'!Q:R,2,0)&"-"&Table4[[#This Row],[Seq]] -> #N/A | O4: =+LEN(Table4[[#This Row],[New Item Code]]) -> #N/A | P4: MP0100 | Q4: Spare parts | S4: Spare parts ABB | T4: ABB
A5: ABB-0006 | B5: OMRON Resistance brake A1000-REV00K6050-IE | C5: Critical Spares-CS | D5: 200.51 | E5: Yes | F5: 1 | G5: =Table4[[#This Row],[Item Cost]]*Table4[[#This Row],[In Stock]] -> 200.51 | H5: Spare Parts | I5: Critical Spares | J5: ABB | K5: Common | L5: Common | M5: =IF(LEN(COUNTIFS($H$1:H5,$H5,$I$1:I5,$I5,$J$1:J5,$J5,$K$1:K5,K5,$L$1:L5,L5))=1,"00"&COUNTIFS($H$1:H5,$H5,$I$1:I5,$I5,$J$1:J5,$J5,$K$1:K5,K5,$L$1:L5,L5),IF(LEN(COUNTIFS($H$1:H5,$H5,$I$1:I5,$I5,$J$1:J5,$J5,$K$1:K5,K5,$L$1:L5,L5))=2,"0"&COUNTIFS($H$1:H5,$H5,$I$1:I5,$I5,$J$1:J5,$J5,$K$1:K5,K5,$L$1:L5,L5),COUNTIFS($H$1:H5,$H5,$I$1:I5,$I5,$J$1:J5,$J5,$K$1:K5,K5,$L$1:L5,L5))) -> 001 | N5: =VLOOKUP(Table4[[#This Row],[Department]],'Mapping code'!A:B,2,0)&"-"&VLOOKUP(Table4[[#This Row],[Category]],'Mapping code'!E:F,2,0)&"-"&VLOOKUP(Table4[[#This Row],[Machine]],'Mapping code'!I:J,2,0)&"-"&VLOOKUP(Table4[[#This Row],[Product Nature]],'Mapping code'!N:O,2,0)&"-"&VLOOKUP(Table4[[#This Row],[Category2]],'Mapping code'!Q:R,2,0)&"-"&Table4[[#This Row],[Seq]] -> #N/A | O5: =+LEN(Table4[[#This Row],[New Item Code]]) -> #N/A | P5: MP0100 | Q5: Spare parts | S5: Spare parts ABB | T5: ABB
A6: ABB-0007 | B6: Pluto B20 v2 2TLA020070R4600 | C6: Critical Spares-CS | D6: 2726.94 | E6: Yes | F6: 1 | G6: =Table4[[#This Row],[Item Cost]]*Table4[[#This Row],[In Stock]] -> 2726.94 | H6: Spare Parts | I6: Critical Spares | J6: ABB | K6: Pluto | L6: Common | M6: =IF(LEN(COUNTIFS($H$1:H6,$H6,$I$1:I6,$I6,$J$1:J6,$J6,$K$1:K6,K6,$L$1:L6,L6))=1,"00"&COUNTIFS($H$1:H6,$H6,$I$1:I6,$I6,$J$1:J6,$J6,$K$1:K6,K6,$L$1:L6,L6),IF(LEN(COUNTIFS($H$1:H6,$H6,$I$1:I6,$I6,$J$1:J6,$J6,$K$1:K6,K6,$L$1:L6,L6))=2,"0"&COUNTIFS($H$1:H6,$H6,$I$1:I6,$I6,$J$1:J6,$J6,$K$1:K6,K6,$L$1:L6,L6),COUNTIFS($H$1:H6,$H6,$I$1:I6,$I6,$J$1:J6,$J6,$K$1:K6,K6,$L$1:L6,L6))) -> 001 | N6: =VLOOKUP(Table4[[#This Row],[Department]],'Mapping code'!A:B,2,0)&"-"&VLOOKUP(Table4[[#This Row],[Category]],'Mapping code'!E:F,2,0)&"-"&VLOOKUP(Table4[[#This Row],[Machine]],'Mapping code'!I:J,2,0)&"-"&VLOOKUP(Table4[[#This Row],[Product Nature]],'Mapping code'!N:O,2,0)&"-"&VLOOKUP(Table4[[#This Row],[Category2]],'Mapping code'!Q:R,2,0)&"-"&Table4[[#This Row],[Seq]] -> #N/A | O6: =+LEN(Table4[[#This Row],[New Item Code]]) -> #N/A | P6: MP0100 | Q6: Spare parts | S6: Spare parts ABB | T6: ABB
A7: ABB-0008 | B7: Pluto B46 v2 2TLA020070R1700 | C7: Critical Spares-CS | D7: 5072.01 | E7: Yes | F7: 1 | G7: =Table4[[#This Row],[Item Cost]]*Table4[[#This Row],[In Stock]] -> 5072.01 | H7: Spare Parts | I7: Critical Spares | J7: ABB | K7: Pluto | L7: Common | M7: =IF(LEN(COUNTIFS($H$1:H7,$H7,$I$1:I7,$I7,$J$1:J7,$J7,$K$1:K7,K7,$L$1:L7,L7))=1,"00"&COUNTIFS($H$1:H7,$H7,$I$1:I7,$I7,$J$1:J7,$J7,$K$1:K7,K7,$L$1:L7,L7),IF(LEN(COUNTIFS($H$1:H7,$H7,$I$1:I7,$I7,$J$1:J7,$J7,$K$1:K7,K7,$L$1:L7,L7))=2,"0"&COUNTIFS($H$1:H7,$H7,$I$1:I7,$I7,$J$1:J7,$J7,$K$1:K7,K7,$L$1:L7,L7),COUNTIFS($H$1:H7,$H7,$I$1:I7,$I7,$J$1:J7,$J7,$K$1:K7,K7,$L$1:L7,L7))) -> 002 | N7: =VLOOKUP(Table4[[#This Row],[Department]],'Mapping code'!A:B,2,0)&"-"&VLOOKUP(Table4[[#This Row],[Category]],'Mapping code'!E:F,2,0)&"-"&VLOOKUP(Table4[[#This Row],[Machine]],'Mapping code'!I:J,2,0)&"-"&VLOOKUP(Table4[[#This Row],[Product Nature]],'Mapping code'!N:O,2,0)&"-"&VLOOKUP(Table4[[#This Row],[Category2]],'Mapping code'!Q:R,2,0)&"-"&Table4[[#This Row],[Seq]] -> #N/A | O7: =+LEN(Table4[[#This Row],[New Item Code]]) -> #N/A | P7: MP0100 | Q7: Spare parts | S7: Spare parts ABB | T7: ABB
A8: ABB-0009 | B8: Pluto gate 2TLA020071R9300 | C8: Critical Spares-CS | D8: 1403.57 | E8: Yes | F8: 1 | G8: =Table4[[#This Row],[Item Cost]]*Table4[[#This Row],[In Stock]] -> 1403.57 | H8: Spare Parts | I8: Critical Spares | J8: ABB | K8: Pluto | L8: Common | M8: =IF(LEN(COUNTIFS($H$1:H8,$H8,$I$1:I8,$I8,$J$1:J8,$J8,$K$1:K8,K8,$L$1:L8,L8))=1,"00"&COUNTIFS($H$1:H8,$H8,$I$1:I8,$I8,$J$1:J8,$J8,$K$1:K8,K8,$L$1:L8,L8),IF(LEN(COUNTIFS($H$1:H8,$H8,$I$1:I8,$I8,$J$1:J8,$J8,$K$1:K8,K8,$L$1:L8,L8))=2,"0"&COUNTIFS($H$1:H8,$H8,$I$1:I8,$I8,$J$1:J8,$J8,$K$1:K8,K8,$L$1:L8,L8),COUNTIFS($H$1:H8,$H8,$I$1:I8,$I8,$J$1:J8,$J8,$K$1:K8,K8,$L$1:L8,L8))) -> 003 | N8: =VLOOKUP(Table4[[#This Row],[Department]],'Mapping code'!A:B,2,0)&"-"&VLOOKUP(Table4[[#This Row],[Category]],'Mapping code'!E:F,2,0)&"-"&VLOOKUP(Table4[[#This Row],[Machine]],'Mapping code'!I:J,2,0)&"-"&VLOOKUP(Table4[[#This Row],[Product Nature]],'Mapping code'!N:O,2,0)&"-"&VLOOKUP(Table4[[#This Row],[Category2]],'Mapping code'!Q:R,2,0)&"-"&Table4[[#This Row],[Seq]] -> #N/A | O8: =+LEN(Table4[[#This Row],[New Item Code]]) -> #N/A | P8: MP0100 | Q8: Spare parts | S8: Spare parts ABB | T8: ABB
A9: ABB-0010 | B9: ET200 head 6ES7155-6AA01-0BN0 | C9: Critical Spares-CS | D9: 3448.77 | E9: Yes | F9: 1 | G9: =Table4[[#This Row],[Item Cost]]*Table4[[#This Row],[In Stock]] -> 3448.77 | H9: Spare Parts | I9: Critical Spares | J9: ABB | K9: Common | L9: Common | M9: =IF(LEN(COUNTIFS($H$1:H9,$H9,$I$1:I9,$I9,$J$1:J9,$J9,$K$1:K9,K9,$L$1:L9,L9))=1,"00"&COUNTIFS($H$1:H9,$H9,$I$1:I9,$I9,$J$1:J9,$J9,$K$1:K9,K9,$L$1:L9,L9),IF(LEN(COUNTIFS($H$1:H9,$H9,$I$1:I9,$I9,$J$1:J9,$J9,$K$1:K9,K9,$L$1:L9,L9))=2,"0"&COUNTIFS($H$1:H9,$H9,$I$1:I9,$I9,$J$1:J9,$J9,$K$1:K9,K9,$L$1:L9,L9),COUNTIFS($H$1:H9,$H9,$I$1:I9,$I9,$J$1:J9,$J9,$K$1:K9,K9,$L$1:L9,L9))) -> 002 | N9: =VLOOKUP(Table4[[#This Row],[Department]],'Mapping code'!A:B,2,0)&"-"&VLOOKUP(Table4[[#This Row],[Category]],'Mapping code'!E:F,2,0)&"-"&VLOOKUP(Table4[[#This Row],[Machine]],'Mapping code'!I:J,2,0)&"-"&VLOOKUP(Table4[[#This Row],[Product Nature]],'Mapping code'!N:O,2,0)&"-"&VLOOKUP(Table4[[#This Row],[Category2]],'Mapping code'!Q:R,2,0)&"-"&Table4[[#This Row],[Seq]] -> #N/A | O9: =+LEN(Table4[[#This Row],[New Item Code]]) -> #N/A | P9: MP0100 | Q9: Spare parts | S9: Spare parts ABB | T9: ABB
A10: ABB-0011 | B10: ET200 INPUT 6ES7131-6BF01-0BA0 | C10: Critical Spares-CS | D10: 1022.6 | E10: Yes | F10: 1 | G10: =Table4[[#This Row],[Item Cost]]*Table4[[#This Row],[In Stock]] -> 1022.6 | H10: Spare Parts | I10: Critical Spares | J10: ABB | K10: Common | L10: Common | M10: =IF(LEN(COUNTIFS($H$1:H10,$H10,$I$1:I10,$I10,$J$1:J10,$J10,$K$1:K10,K10,$L$1:L10,L10))=1,"00"&COUNTIFS($H$1:H10,$H10,$I$1:I10,$I10,$J$1:J10,$J10,$K$1:K10,K10,$L$1:L10,L10),IF(LEN(COUNTIFS($H$1:H10,$H10,$I$1:I10,$I10,$J$1:J10,$J10,$K$1:K10,K10,$L$1:L10,L10))=2,"0"&COUNTIFS($H$1:H10,$H10,$I$1:I10,$I10,$J$1:J10,$J10,$K$1:K10,K10,$L$1:L10,L10),COUNTIFS($H$1:H10,$H10,$I$1:I10,$I10,$J$1:J10,$J10,$K$1:K10,K10,$L$1:L10,L10))) -> 003 | N10: =VLOOKUP(Table4[[#This Row],[Department]],'Mapping code'!A:B,2,0)&"-"&VLOOKUP(Table4[[#This Row],[Category]],'Mapping code'!E:F,2,0)&"-"&VLOOKUP(Table4[[#This Row],[Machine]],'Mapping code'!I:J,2,0)&"-"&VLOOKUP(Table4[[#This Row],[Product Nature]],'Mapping code'!N:O,2,0)&"-"&VLOOKUP(Table4[[#This Row],[Category2]],'Mapping code'!Q:R,2,0)&"-"&Table4[[#This Row],[Seq]] -> #N/A | O10: =+LEN(Table4[[#This Row],[New Item Code]]) -> #N/A | P10: MP0100 | Q10: Spare parts | S10: Spare parts ABB | T10: ABB
A11: ABB-0012 | B11: ET200 OUTPUT 6ES7132-6BF01-0BA0 | C11: Critical Spares-CS | D11: 1423.62 | E11: Yes | F11: 1 | G11: =Table4[[#This Row],[Item Cost]]*Table4[[#This Row],[In Stock]] -> 1423.62 | H11: Spare Parts | I11: Critical Spares | J11: ABB | K11: Common | L11: Common | M11: =IF(LEN(COUNTIFS($H$1:H11,$H11,$I$1:I11,$I11,$J$1:J11,$J11,$K$1:K11,K11,$L$1:L11,L11))=1,"00"&COUNTIFS($H$1:H11,$H11,$I$1:I11,$I11,$J$1:J11,$J11,$K$1:K11,K11,$L$1:L11,L11),IF(LEN(COUNTIFS($H$1:H11,$H11,$I$1:I11,$I11,$J$1:J11,$J11,$K$1:K11,K11,$L$1:L11,L11))=2,"0"&COUNTIFS($H$1:H11,$H11,$I$1:I11,$I11,$J$1:J11,$J11,$K$1:K11,K11,$L$1:L11,L11),COUNTIFS($H$1:H11,$H11,$I$1:I11,$I11,$J$1:J11,$J11,$K$1:K11,K11,$L$1:L11,L11))) -> 004 | N11: =VLOOKUP(Table4[[#This Row],[Department]],'Mapping code'!A:B,2,0)&"-"&VLOOKUP(Table4[[#This Row],[Category]],'Mapping code'!E:F,2,0)&"-"&VLOOKUP(Table4[[#This Row],[Machine]],'Mapping code'!I:J,2,0)&"-"&VLOOKUP(Table4[[#This Row],[Product Nature]],'Mapping code'!N:O,2,0)&"-"&VLOOKUP(Table4[[#This Row],[Category2]],'Mapping code'!Q:R,2,0)&"-"&Table4[[#This Row],[Seq]] -> #N/A | O11: =+LEN(Table4[[#This Row],[New Item Code]]) -> #N/A | P11: MP0100 | Q11: Spare parts | S11: Spare parts ABB | T11: ABB
A12: ABB-0013 | B12: ET200 insulated base 6ES7193-6BP20-0DA0 | C12: Critical Spares-CS | D12: 962.45 | E12: Yes | F12: 1 | G12: =Table4[[#This Row],[Item Cost]]*Table4[[#This Row],[In Stock]] -> 962.45 | H12: Spare Parts | I12: Connector | J12: ABB | K12: Common | L12: Common | M12: =IF(LEN(COUNTIFS($H$1:H12,$H12,$I$1:I12,$I12,$J$1:J12,$J12,$K$1:K12,K12,$L$1:L12,L12))=1,"00"&COUNTIFS($H$1:H12,$H12,$I$1:I12,$I12,$J$1:J12,$J12,$K$1:K12,K12,$L$1:L12,L12),IF(LEN(COUNTIFS($H$1:H12,$H12,$I$1:I12,$I12,$J$1:J12,$J12,$K$1:K12,K12,$L$1:L12,L12))=2,"0"&COUNTIFS($H$1:H12,$H12,$I$1:I12,$I12,$J$1:J12,$J12,$K$1:K12,K12,$L$1:L12,L12),COUNTIFS($H$1:H12,$H12,$I$1:I12,$I12,$J$1:J12,$J12,$K$1:K12,K12,$L$1:L12,L12))) -> 001 | N12: =VLOOKUP(Table4[[#This Row],[Department]],'Mapping code'!A:B,2,0)&"-"&VLOOKUP(Table4[[#This Row],[Category]],'Mapping code'!E:F,2,0)&"-"&VLOOKUP(Table4[[#This Row],[Machine]],'Mapping code'!I:J,2,0)&"-"&VLOOKUP(Table4[[#This Row],[Product Nature]],'Mapping code'!N:O,2,0)&"-"&VLOOKUP(Table4[[#This Row],[Category2]],'Mapping code'!Q:R,2,0)&"-"&Table4[[#This Row],[Seq]] -> #N/A | O12: =+LEN(Table4[[#This Row],[New Item Code]]) -> #N/A | P12: MP0100 | Q12: Spare parts | S12: Spare parts ABB | T12: ABB
A13: ABB-0014 | B13: Smile 11 EA Tina 2TLA030050R0000 | C13: Critical Spares-CS | D13: 320.82 | E13: Yes | F13: 1 | G13: =Table4[[#This Row],[Item Cost]]*Table4[[#This Row],[In Stock]] -> 320.82 | H13: Spare Parts | I13: Critical Spares | J13: ABB | K13: Common | L13: Common | M13: =IF(LEN(COUNTIFS($H$1:H13,$H13,$I$1:I13,$I13,$J$1:J13,$J13,$K$1:K13,K13,$L$1:L13,L13))=1,"00"&COUNTIFS($H$1:H13,$H13,$I$1:I13,$I13,$J$1:J13,$J13,$K$1:K13,K13,$L$1:L13,L13),IF(LEN(COUNTIFS($H$1:H13,$H13,$I$1:I13,$I13,$J$1:J13,$J13,$K$1:K13,K13,$L$1:L13,L13))=2,"0"&COUNTIFS($H$1:H13,$H13,$I$1:I13,$I13,$J$1:J13,$J13,$K$1:K13,K13,$L$1:L13,L13),COUNTIFS($H$1:H13,$H13,$I$1:I13,$I13,$J$1:J13,$J13,$K$1:K13,K13,$L$1:L13,L13))) -> 005 | N13: =VLOOKUP(Table4[[#This Row],[Department]],'Mapping code'!A:B,2,0)&"-"&VLOOKUP(Table4[[#This Row],[Category]],'Mapping code'!E:F,2,0)&"-"&VLOOKUP(Table4[[#This Row],[Machine]],'Mapping code'!I:J,2,0)&"-"&VLOOKUP(Table4[[#This Row],[Product Nature]],'Mapping code'!N:O,2,0)&"-"&VLOOKUP(Table4[[#This Row],[Category2]],'Mapping code'!Q:R,2,0)&"-"&Table4[[#This Row],[Seq]] -> #N/A | O13: =+LEN(Table4[[#This Row],[New Item Code]]) -> #N/A | P13: MP0100 | Q13: Spare parts | S13: Spare parts ABB | T13: ABB
... A55: ABB-0057 | B55: Omron E2E-X8B1TL18-M1 | C55: Normal Spares-NS | D55: 149 | E55: Yes | F55: 10 | G55: =Table4[[#This Row],[Item Cost]]*Table4[[#This Row],[In Stock]] -> 1490 | H55: Spare Parts | I55: Normal Spares | J55: ABB | K55: Common | L55: Common | M55: =IF(LEN(COUNTIFS($H$1:H55,$H55,$I$1:I55,$I55,$J$1:J55,$J55,$K$1:K55,K55,$L$1:L55,L55))=1,"00"&COUNTIFS($H$1:H55,$H55,$I$1:I55,$I55,$J$1:J55,$J55,$K$1:K55,K55,$L$1:L55,L55),IF(LEN(COUNTIFS($H$1:H55,$H55,$I$1:I55,$I55,$J$1:J55,$J55,$K$1:K55,K55,$L$1:L55,L55))=2,"0"&COUNTIFS($H$1:H55,$H55,$I$1:I55,$I55,$J$1:J55,$J55,$K$1:K55,K55,$L$1:L55,L55),COUNTIFS($H$1:H55,$H55,$I$1:I55,$I55,$J$1:J55,$J55,$K$1:K55,K55,$L$1:L55,L55))) -> 013 | N55: =VLOOKUP(Table4[[#This Row],[Department]],'Mapping code'!A:B,2,0)&"-"&VLOOKUP(Table4[[#This Row],[Category]],'Mapping code'!E:F,2,0)&"-"&VLOOKUP(Table4[[#This Row],[Machine]],'Mapping code'!I:J,2,0)&"-"&VLOOKUP(Table4[[#This Row],[Product Nature]],'Mapping code'!N:O,2,0)&"-"&VLOOKUP(Table4[[#This Row],[Category2]],'Mapping code'!Q:R,2,0)&"-"&Table4[[#This Row],[Seq]] -> #N/A | O55: =+LEN(Table4[[#This Row],[New Item Code]]) -> #N/A | P55: MP0100 | Q55: Spare parts | S55: Spare parts ABB | T55: ABB
A56: ABB-0058 | B56: Refurbished - Electrospindle | C56: Normal Spares-NS | D56: 10500 | E56: Yes | F56: 1 | G56: =Table4[[#This Row],[Item Cost]]*Table4[[#This Row],[In Stock]] -> 10500 | H56: Spare Parts | I56: Normal Spares | J56: ABB | K56: Spindle | L56: Common | M56: =IF(LEN(COUNTIFS($H$1:H56,$H56,$I$1:I56,$I56,$J$1:J56,$J56,$K$1:K56,K56,$L$1:L56,L56))=1,"00"&COUNTIFS($H$1:H56,$H56,$I$1:I56,$I56,$J$1:J56,$J56,$K$1:K56,K56,$L$1:L56,L56),IF(LEN(COUNTIFS($H$1:H56,$H56,$I$1:I56,$I56,$J$1:J56,$J56,$K$1:K56,K56,$L$1:L56,L56))=2,"0"&COUNTIFS($H$1:H56,$H56,$I$1:I56,$I56,$J$1:J56,$J56,$K$1:K56,K56,$L$1:L56,L56),COUNTIFS($H$1:H56,$H56,$I$1:I56,$I56,$J$1:J56,$J56,$K$1:K56,K56,$L$1:L56,L56))) -> 002 | N56: =VLOOKUP(Table4[[#This Row],[Department]],'Mapping code'!A:B,2,0)&"-"&VLOOKUP(Table4[[#This Row],[Category]],'Mapping code'!E:F,2,0)&"-"&VLOOKUP(Table4[[#This Row],[Machine]],'Mapping code'!I:J,2,0)&"-"&VLOOKUP(Table4[[#This Row],[Product Nature]],'Mapping code'!N:O,2,0)&"-"&VLOOKUP(Table4[[#This Row],[Category2]],'Mapping code'!Q:R,2,0)&"-"&Table4[[#This Row],[Seq]] -> #N/A | O56: =+LEN(Table4[[#This Row],[New Item Code]]) -> #N/A | P56: MP0100 | Q56: Spare parts | S56: Spare parts ABB | T56: #N/A
A57: ABBFX-001 | B57: BI2-EG08K-AP6X-V1131 Inductive sensor TURCK M8x1 | C57: Normal Spares-NS | D57: 82 | E57: Yes | F57: 4 | G57: =Table4[[#This Row],[Item Cost]]*Table4[[#This Row],[In Stock]] -> 328 | H57: Spare Parts | I57: Normal Spares | J57: ABB | K57: Common | L57: Common | M57: =IF(LEN(COUNTIFS($H$1:H57,$H57,$I$1:I57,$I57,$J$1:J57,$J57,$K$1:K57,K57,$L$1:L57,L57))=1,"00"&COUNTIFS($H$1:H57,$H57,$I$1:I57,$I57,$J$1:J57,$J57,$K$1:K57,K57,$L$1:L57,L57),IF(LEN(COUNTIFS($H$1:H57,$H57,$I$1:I57,$I57,$J$1:J57,$J57,$K$1:K57,K57,$L$1:L57,L57))=2,"0"&COUNTIFS($H$1:H57,$H57,$I$1:I57,$I57,$J$1:J57,$J57,$K$1:K57,K57,$L$1:L57,L57),COUNTIFS($H$1:H57,$H57,$I$1:I57,$I57,$J$1:J57,$J57,$K$1:K57,K57,$L$1:L57,L57))) -> 014 | N57: =VLOOKUP(Table4[[#This Row],[Department]],'Mapping code'!A:B,2,0)&"-"&VLOOKUP(Table4[[#This Row],[Category]],'Mapping code'!E:F,2,0)&"-"&VLOOKUP(Table4[[#This Row],[Machine]],'Mapping code'!I:J,2,0)&"-"&VLOOKUP(Table4[[#This Row],[Product Nature]],'Mapping code'!N:O,2,0)&"-"&VLOOKUP(Table4[[#This Row],[Category2]],'Mapping code'!Q:R,2,0)&"-"&Table4[[#This Row],[Seq]] -> #N/A | O57: =+LEN(Table4[[#This Row],[New Item Code]]) -> #N/A | P57: MP0100 | Q57: Spare parts | S57: Spare parts ABB | T57: ABB
A58: ABBFX-002 | B58: SWKP3-2 P00 TURCK M8x1 cable with LED | C58: Normal Spares-NS | D58: 64.5 | E58: Yes | F58: 4 | G58: =Table4[[#This Row],[Item Cost]]*Table4[[#This Row],[In Stock]] -> 258 | H58: Spare Parts | I58: Normal Spares | J58: ABB | K58: Common | L58: Common | M58: =IF(LEN(COUNTIFS($H$1:H58,$H58,$I$1:I58,$I58,$J$1:J58,$J58,$K$1:K58,K58,$L$1:L58,L58))=1,"00"&COUNTIFS($H$1:H58,$H58,$I$1:I58,$I58,$J$1:J58,$J58,$K$1:K58,K58,$L$1:L58,L58),IF(LEN(COUNTIFS($H$1:H58,$H58,$I$1:I58,$I58,$J$1:J58,$J58,$K$1:K58,K58,$L$1:L58,L58))=2,"0"&COUNTIFS($H$1:H58,$H58,$I$1:I58,$I58,$J$1:J58,$J58,$K$1:K58,K58,$L$1:L58,L58),COUNTIFS($H$1:H58,$H58,$I$1:I58,$I58,$J$1:J58,$J58,$K$1:K58,K58,$L$1:L58,L58))) -> 015 | N58: =VLOOKUP(Table4[[#This Row],[Department]],'Mapping code'!A:B,2,0)&"-"&VLOOKUP(Table4[[#This Row],[Category]],'Mapping code'!E:F,2,0)&"-"&VLOOKUP(Table4[[#This Row],[Machine]],'Mapping code'!I:J,2,0)&"-"&VLOOKUP(Table4[[#This Row],[Product Nature]],'Mapping code'!N:O,2,0)&"-"&VLOOKUP(Table4[[#This Row],[Category2]],'Mapping code'!Q:R,2,0)&"-"&Table4[[#This Row],[Seq]] -> #N/A | O58: =+LEN(Table4[[#This Row],[New Item Code]]) -> #N/A | P58: MP0100 | Q58: Spare parts | S58: Spare parts ABB | T58: ABB
A59: ABBFX-003 | B59: TBEN-S2-8DXP Hub | C59: Normal Spares-NS | D59: 1077 | E59: Yes | F59: 1 | G59: =Table4[[#This Row],[Item Cost]]*Table4[[#This Row],[In Stock]] -> 1077 | H59: Spare Parts | I59: Normal Spares | J59: ABB | K59: Common | L59: Common | M59: =IF(LEN(COUNTIFS($H$1:H59,$H59,$I$1:I59,$I59,$J$1:J59,$J59,$K$1:K59,K59,$L$1:L59,L59))=1,"00"&COUNTIFS($H$1:H59,$H59,$I$1:I59,$I59,$J$1:J59,$J59,$K$1:K59,K59,$L$1:L59,L59),IF(LEN(COUNTIFS($H$1:H59,$H59,$I$1:I59,$I59,$J$1:J59,$J59,$K$1:K59,K59,$L$1:L59,L59))=2,"0"&COUNTIFS($H$1:H59,$H59,$I$1:I59,$I59,$J$1:J59,$J59,$K$1:K59,K59,$L$1:L59,L59),COUNTIFS($H$1:H59,$H59,$I$1:I59,$I59,$J$1:J59,$J59,$K$1:K59,K59,$L$1:L59,L59))) -> 016 | N59: =VLOOKUP(Table4[[#This Row],[Department]],'Mapping code'!A:B,2,0)&"-"&VLOOKUP(Table4[[#This Row],[Category]],'Mapping code'!E:F,2,0)&"-"&VLOOKUP(Table4[[#This Row],[Machine]],'Mapping code'!I:J,2,0)&"-"&VLOOKUP(Table4[[#This Row],[Product Nature]],'Mapping code'!N:O,2,0)&"-"&VLOOKUP(Table4[[#This Row],[Category2]],'Mapping code'!Q:R,2,0)&"-"&Table4[[#This Row],[Seq]] -> #N/A | O59: =+LEN(Table4[[#This Row],[New Item Code]]) -> #N/A | P59: MP0100 | Q59: Spare parts | S59: Spare parts ABB | T59: ABB
A60: ABBFX-004 | B60: BI4-M12-AP6X-H1141 Inductive TURCK sensor M12x1 | C60: Normal Spares-NS | D60: 55 | E60: Yes | F60: 1 | G60: =Table4[[#This Row],[Item Cost]]*Table4[[#This Row],[In Stock]] -> 55 | H60: Spare Parts | I60: Normal Spares | J60: ABB | K60: Common | L60: Common | M60: =IF(LEN(COUNTIFS($H$1:H60,$H60,$I$1:I60,$I60,$J$1:J60,$J60,$K$1:K60,K60,$L$1:L60,L60))=1,"00"&COUNTIFS($H$1:H60,$H60,$I$1:I60,$I60,$J$1:J60,$J60,$K$1:K60,K60,$L$1:L60,L60),IF(LEN(COUNTIFS($H$1:H60,$H60,$I$1:I60,$I60,$J$1:J60,$J60,$K$1:K60,K60,$L$1:L60,L60))=2,"0"&COUNTIFS($H$1:H60,$H60,$I$1:I60,$I60,$J$1:J60,$J60,$K$1:K60,K60,$L$1:L60,L60),COUNTIFS($H$1:H60,$H60,$I$1:I60,$I60,$J$1:J60,$J60,$K$1:K60,K60,$L$1:L60,L60))) -> 017 | N60: =VLOOKUP(Table4[[#This Row],[Department]],'Mapping code'!A:B,2,0)&"-"&VLOOKUP(Table4[[#This Row],[Category]],'Mapping code'!E:F,2,0)&"-"&VLOOKUP(Table4[[#This Row],[Machine]],'Mapping code'!I:J,2,0)&"-"&VLOOKUP(Table4[[#This Row],[Product Nature]],'Mapping code'!N:O,2,0)&"-"&VLOOKUP(Table4[[#This Row],[Category2]],'Mapping code'!Q:R,2,0)&"-"&Table4[[#This Row],[Seq]] -> #N/A | O60: =+LEN(Table4[[#This Row],[New Item Code]]) -> #N/A | P60: MP0100 | Q60: Spare parts | S60: Spare parts ABB | T60: ABB
A61: ABBFX-005 | B61: 6814076 TURCK TBEN-S2-8DXP 2A | C61: Normal Spares-NS | D61: 1077 | E61: Yes | F61: 1 | G61: =Table4[[#This Row],[Item Cost]]*Table4[[#This Row],[In Stock]] -> 1077 | H61: Spare Parts | I61: Normal Spares | J61: ABB | K61: Common | L61: Common | M61: =IF(LEN(COUNTIFS($H$1:H61,$H61,$I$1:I61,$I61,$J$1:J61,$J61,$K$1:K61,K61,$L$1:L61,L61))=1,"00"&COUNTIFS($H$1:H61,$H61,$I$1:I61,$I61,$J$1:J61,$J61,$K$1:K61,K61,$L$1:L61,L61),IF(LEN(COUNTIFS($H$1:H61,$H61,$I$1:I61,$I61,$J$1:J61,$J61,$K$1:K61,K61,$L$1:L61,L61))=2,"0"&COUNTIFS($H$1:H61,$H61,$I$1:I61,$I61,$J$1:J61,$J61,$K$1:K61,K61,$L$1:L61,L61),COUNTIFS($H$1:H61,$H61,$I$1:I61,$I61,$J$1:J61,$J61,$K$1:K61,K61,$L$1:L61,L61))) -> 018 | N61: =VLOOKUP(Table4[[#This Row],[Department]],'Mapping code'!A:B,2,0)&"-"&VLOOKUP(Table4[[#This Row],[Category]],'Mapping code'!E:F,2,0)&"-"&VLOOKUP(Table4[[#This Row],[Machine]],'Mapping code'!I:J,2,0)&"-"&VLOOKUP(Table4[[#This Row],[Product Nature]],'Mapping code'!N:O,2,0)&"-"&VLOOKUP(Table4[[#This Row],[Category2]],'Mapping code'!Q:R,2,0)&"-"&Table4[[#This Row],[Seq]] -> #N/A | O61: =+LEN(Table4[[#This Row],[New Item Code]]) -> #N/A | P61: MP0100 | Q61: Spare parts | S61: Spare parts ABB | T61: ABB
A62: ABBFX-006 | B62: 0471153 SPC 40 Positioning pin SCHUNK | C62: Normal Spares-NS | D62: 0 | E62: Yes | F62: 0 | G62: =Table4[[#This Row],[Item Cost]]*Table4[[#This Row],[In Stock]] -> 0 | H62: Spare Parts | I62: Normal Spares | J62: ABB | K62: Common | L62: Common | M62: =IF(LEN(COUNTIFS($H$1:H62,$H62,$I$1:I62,$I62,$J$1:J62,$J62,$K$1:K62,K62,$L$1:L62,L62))=1,"00"&COUNTIFS($H$1:H62,$H62,$I$1:I62,$I62,$J$1:J62,$J62,$K$1:K62,K62,$L$1:L62,L62),IF(LEN(COUNTIFS($H$1:H62,$H62,$I$1:I62,$I62,$J$1:J62,$J62,$K$1:K62,K62,$L$1:L62,L62))=2,"0"&COUNTIFS($H$1:H62,$H62,$I$1:I62,$I62,$J$1:J62,$J62,$K$1:K62,K62,$L$1:L62,L62),COUNTIFS($H$1:H62,$H62,$I$1:I62,$I62,$J$1:J62,$J62,$K$1:K62,K62,$L$1:L62,L62))) -> 019 | N62: =VLOOKUP(Table4[[#This Row],[Department]],'Mapping code'!A:B,2,0)&"-"&VLOOKUP(Table4[[#This Row],[Category]],'Mapping code'!E:F,2,0)&"-"&VLOOKUP(Table4[[#This Row],[Machine]],'Mapping code'!I:J,2,0)&"-"&VLOOKUP(Table4[[#This Row],[Product Nature]],'Mapping code'!N:O,2,0)&"-"&VLOOKUP(Table4[[#This Row],[Category2]],'Mapping code'!Q:R,2,0)&"-"&Table4[[#This Row],[Seq]] -> #N/A | O62: =+LEN(Table4[[#This Row],[New Item Code]]) -> #N/A | P62: MP0100 | Q62: Spare parts | S62: Spare parts ABB | T62: ABB
A63: ABBFX-007 | B63: 471153 SPC 40RF Fastening pin | C63: Normal Spares-NS | D63: 238.715 | E63: Yes | F63: 2 | G63: =Table4[[#This Row],[Item Cost]]*Table4[[#This Row],[In Stock]] -> 477.43 | H63: Spare Parts | I63: Normal Spares | J63: ABB | K63: Common | L63: Common | M63: =IF(LEN(COUNTIFS($H$1:H63,$H63,$I$1:I63,$I63,$J$1:J63,$J63,$K$1:K63,K63,$L$1:L63,L63))=1,"00"&COUNTIFS($H$1:H63,$H63,$I$1:I63,$I63,$J$1:J63,$J63,$K$1:K63,K63,$L$1:L63,L63),IF(LEN(COUNTIFS($H$1:H63,$H63,$I$1:I63,$I63,$J$1:J63,$J63,$K$1:K63,K63,$L$1:L63,L63))=2,"0"&COUNTIFS($H$1:H63,$H63,$I$1:I63,$I63,$J$1:J63,$J63,$K$1:K63,K63,$L$1:L63,L63),COUNTIFS($H$1:H63,$H63,$I$1:I63,$I63,$J$1:J63,$J63,$K$1:K63,K63,$L$1:L63,L63))) -> 020 | N63: =VLOOKUP(Table4[[#This Row],[Department]],'Mapping code'!A:B,2,0)&"-"&VLOOKUP(Table4[[#This Row],[Category]],'Mapping code'!E:F,2,0)&"-"&VLOOKUP(Table4[[#This Row],[Machine]],'Mapping code'!I:J,2,0)&"-"&VLOOKUP(Table4[[#This Row],[Product Nature]],'Mapping code'!N:O,2,0)&"-"&VLOOKUP(Table4[[#This Row],[Category2]],'Mapping code'!Q:R,2,0)&"-"&Table4[[#This Row],[Seq]] -> #N/A | O63: =+LEN(Table4[[#This Row],[New Item Code]]) -> #N/A | P63: MP0100 | Q63: Spare parts | S63: Spare parts ABB | T63: ABB
A64: ABBFX-008 | B64: 471152 SPB 40RF Alignment pin | C64: Normal Spares-NS | D64: 326.855 | E64: Yes | F64: 2 | G64: =Table4[[#This Row],[Item Cost]]*Table4[[#This Row],[In Stock]] -> 653.71 | H64: Spare Parts | I64: Normal Spares | J64: ABB | K64: Common | L64: Common | M64: =IF(LEN(COUNTIFS($H$1:H64,$H64,$I$1:I64,$I64,$J$1:J64,$J64,$K$1:K64,K64,$L$1:L64,L64))=1,"00"&COUNTIFS($H$1:H64,$H64,$I$1:I64,$I64,$J$1:J64,$J64,$K$1:K64,K64,$L$1:L64,L64),IF(LEN(COUNTIFS($H$1:H64,$H64,$I$1:I64,$I64,$J$1:J64,$J64,$K$1:K64,K64,$L$1:L64,L64))=2,"0"&COUNTIFS($H$1:H64,$H64,$I$1:I64,$I64,$J$1:J64,$J64,$K$1:K64,K64,$L$1:L64,L64),COUNTIFS($H$1:H64,$H64,$I$1:I64,$I64,$J$1:J64,$J64,$K$1:K64,K64,$L$1:L64,L64))) -> 021 | N64: =VLOOKUP(Table4[[#This Row],[Department]],'Mapping code'!A:B,2,0)&"-"&VLOOKUP(Table4[[#This Row],[Category]],'Mapping code'!E:F,2,0)&"-"&VLOOKUP(Table4[[#This Row],[Machine]],'Mapping code'!I:J,2,0)&"-"&VLOOKUP(Table4[[#This Row],[Product Nature]],'Mapping code'!N:O,2,0)&"-"&VLOOKUP(Table4[[#This Row],[Category2]],'Mapping code'!Q:R,2,0)&"-"&Table4[[#This Row],[Seq]] -> #N/A | O64: =+LEN(Table4[[#This Row],[New Item Code]]) -> #N/A | P64: MP0100 | Q64: Spare parts | S64: Spare parts ABB | T64: ABB
A65: ABBFX-009 | B65: 0471151 SPA 40 Positioning pin SCHUNK | C65: Normal Spares-NS | D65: 275.44 | E65: Yes | F65: 2 | G65: =Table4[[#This Row],[Item Cost]]*Table4[[#This Row],[In Stock]] -> 550.88 | H65: Spare Parts | I65: Normal Spares | J65: ABB | K65: Common | L65: Common | M65: =IF(LEN(COUNTIFS($H$1:H65,$H65,$I$1:I65,$I65,$J$1:J65,$J65,$K$1:K65,K65,$L$1:L65,L65))=1,"00"&COUNTIFS($H$1:H65,$H65,$I$1:I65,$I65,$J$1:J65,$J65,$K$1:K65,K65,$L$1:L65,L65),IF(LEN(COUNTIFS($H$1:H65,$H65,$I$1:I65,$I65,$J$1:J65,$J65,$K$1:K65,K65,$L$1:L65,L65))=2,"0"&COUNTIFS($H$1:H65,$H65,$I$1:I65,$I65,$J$1:J65,$J65,$K$1:K65,K65,$L$1:L65,L65),COUNTIFS($H$1:H65,$H65,$I$1:I65,$I65,$J$1:J65,$J65,$K$1:K65,K65,$L$1:L65,L65))) -> 022 | N65: =VLOOKUP(Table4[[#This Row],[Department]],'Mapping code'!A:B,2,0)&"-"&VLOOKUP(Table4[[#This Row],[Category]],'Mapping code'!E:F,2,0)&"-"&VLOOKUP(Table4[[#This Row],[Machine]],'Mapping code'!I:J,2,0)&"-"&VLOOKUP(Table4[[#This Row],[Product Nature]],'Mapping code'!N:O,2,0)&"-"&VLOOKUP(Table4[[#This Row],[Category2]],'Mapping code'!Q:R,2,0)&"-"&Table4[[#This Row],[Seq]] -> #N/A | O65: =+LEN(Table4[[#This Row],[New Item Code]]) -> #N/A | P65: MP0100 | Q65: Spare parts | S65: Spare parts ABB | T65: ABB
A66: ABBFX-010 | B66: 0471152 SPB 40 Positioning pin SCHUNK | C66: Normal Spares-NS | D66: 0 | E66: Yes | F66: 0 | G66: =Table4[[#This Row],[Item Cost]]*Table4[[#This Row],[In Stock]] -> 0 | H66: Spare Parts | I66: Normal Spares | J66: ABB | K66: Common | L66: Common | M66: =IF(LEN(COUNTIFS($H$1:H66,$H66,$I$1:I66,$I66,$J$1:J66,$J66,$K$1:K66,K66,$L$1:L66,L66))=1,"00"&COUNTIFS($H$1:H66,$H66,$I$1:I66,$I66,$J$1:J66,$J66,$K$1:K66,K66,$L$1:L66,L66),IF(LEN(COUNTIFS($H$1:H66,$H66,$I$1:I66,$I66,$J$1:J66,$J66,$K$1:K66,K66,$L$1:L66,L66))=2,"0"&COUNTIFS($H$1:H66,$H66,$I$1:I66,$I66,$J$1:J66,$J66,$K$1:K66,K66,$L$1:L66,L66),COUNTIFS($H$1:H66,$H66,$I$1:I66,$I66,$J$1:J66,$J66,$K$1:K66,K66,$L$1:L66,L66))) -> 023 | N66: =VLOOKUP(Table4[[#This Row],[Department]],'Mapping code'!A:B,2,0)&"-"&VLOOKUP(Table4[[#This Row],[Category]],'Mapping code'!E:F,2,0)&"-"&VLOOKUP(Table4[[#This Row],[Machine]],'Mapping code'!I:J,2,0)&"-"&VLOOKUP(Table4[[#This Row],[Product Nature]],'Mapping code'!N:O,2,0)&"-"&VLOOKUP(Table4[[#This Row],[Category2]],'Mapping code'!Q:R,2,0)&"-"&Table4[[#This Row],[Seq]] -> #N/A | O66: =+LEN(Table4[[#This Row],[New Item Code]]) -> #N/A | P66: MP0100 | Q66: Spare parts | S66: Spare parts ABB | T66: ABB
A67: ABBFX-011 | B67: 471151 SPA 40RF Retaining pin | C67: Normal Spares-NS | D67: 0 | E67: Yes | F67: 0 | G67: =Table4[[#This Row],[Item Cost]]*Table4[[#This Row],[In Stock]] -> 0 | H67: Spare Parts | I67: Normal Spares | J67: ABB | K67: Common | L67: Common | M67: =IF(LEN(COUNTIFS($H$1:H67,$H67,$I$1:I67,$I67,$J$1:J67,$J67,$K$1:K67,K67,$L$1:L67,L67))=1,"00"&COUNTIFS($H$1:H67,$H67,$I$1:I67,$I67,$J$1:J67,$J67,$K$1:K67,K67,$L$1:L67,L67),IF(LEN(COUNTIFS($H$1:H67,$H67,$I$1:I67,$I67,$J$1:J67,$J67,$K$1:K67,K67,$L$1:L67,L67))=2,"0"&COUNTIFS($H$1:H67,$H67,$I$1:I67,$I67,$J$1:J67,$J67,$K$1:K67,K67,$L$1:L67,L67),COUNTIFS($H$1:H67,$H67,$I$1:I67,$I67,$J$1:J67,$J67,$K$1:K67,K67,$L$1:L67,L67))) -> 024 | N67: =VLOOKUP(Table4[[#This Row],[Department]],'Mapping code'!A:B,2,0)&"-"&VLOOKUP(Table4[[#This Row],[Category]],'Mapping code'!E:F,2,0)&"-"&VLOOKUP(Table4[[#This Row],[Machine]],'Mapping code'!I:J,2,0)&"-"&VLOOKUP(Table4[[#This Row],[Product Nature]],'Mapping code'!N:O,2,0)&"-"&VLOOKUP(Table4[[#This Row],[Category2]],'Mapping code'!Q:R,2,0)&"-"&Table4[[#This Row],[Seq]] -> #N/A | O67: =+LEN(Table4[[#This Row],[New Item Code]]) -> #N/A | P67: MP0100 | Q67: Spare parts | S67: Spare parts ABB | T67: ABB
A68: ABBFX-012 | B68: 1674901 Clamped contact CK1 6-ED-0 37ST | C68: Normal Spares-NS | D68: 4.59 | E68: Yes | F68: 0 | G68: =Table4[[#This Row],[Item Cost]]*Table4[[#This Row],[In Stock]] -> 0 | H68: Spare Parts | I68: Normal Spares | J68: ABB | K68: Common | L68: Common | M68: =IF(LEN(COUNTIFS($H$1:H68,$H68,$I$1:I68,$I68,$J$1:J68,$J68,$K$1:K68,K68,$L$1:L68,L68))=1,"00"&COUNTIFS($H$1:H68,$H68,$I$1:I68,$I68,$J$1:J68,$J68,$K$1:K68,K68,$L$1:L68,L68),IF(LEN(COUNTIFS($H$1:H68,$H68,$I$1:I68,$I68,$J$1:J68,$J68,$K$1:K68,K68,$L$1:L68,L68))=2,"0"&COUNTIFS($H$1:H68,$H68,$I$1:I68,$I68,$J$1:J68,$J68,$K$1:K68,K68,$L$1:L68,L68),COUNTIFS($H$1:H68,$H68,$I$1:I68,$I68,$J$1:J68,$J68,$K$1:K68,K68,$L$1:L68,L68))) -> 025 | N68: =VLOOKUP(Table4[[#This Row],[Department]],'Mapping code'!A:B,2,0)&"-"&VLOOKUP(Table4[[#This Row],[Category]],'Mapping code'!E:F,2,0)&"-"&VLOOKUP(Table4[[#This Row],[Machine]],'Mapping code'!I:J,2,0)&"-"&VLOOKUP(Table4[[#This Row],[Product Nature]],'Mapping code'!N:O,2,0)&"-"&VLOOKUP(Table4[[#This Row],[Category2]],'Mapping code'!Q:R,2,0)&"-"&Table4[[#This Row],[Seq]] -> #N/A | O68: =+LEN(Table4[[#This Row],[New Item Code]]) -> #N/A | P68: MP0100 | Q68: Spare parts | S68: Spare parts ABB | T68: ABB
... A108: ABBFX-052 | B108: Valve block ES 06-08-38 (A B P T ) | C108: Normal Spares-NS | D108: 0 | E108: Yes | F108: 0 | G108: =Table4[[#This Row],[Item Cost]]*Table4[[#This Row],[In Stock]] -> 0 | H108: Spare Parts | I108: Normal Spares | J108: ABB | K108: Common | L108: Common | M108: =IF(LEN(COUNTIFS($H$1:H108,$H108,$I$1:I108,$I108,$J$1:J108,$J108,$K$1:K108,K108,$L$1:L108,L108))=1,"00"&COUNTIFS($H$1:H108,$H108,$I$1:I108,$I108,$J$1:J108,$J108,$K$1:K108,K108,$L$1:L108,L108),IF(LEN(COUNTIFS($H$1:H108,$H108,$I$1:I108,$I108,$J$1:J108,$J108,$K$1:K108,K108,$L$1:L108,L108))=2,"0"&COUNTIFS($H$1:H108,$H108,$I$1:I108,$I108,$J$1:J108,$J108,$K$1:K108,K108,$L$1:L108,L108),COUNTIFS($H$1:H108,$H108,$I$1:I108,$I108,$J$1:J108,$J108,$K$1:K108,K108,$L$1:L108,L108))) -> 054 | N108: =VLOOKUP(Table4[[#This Row],[Department]],'Mapping code'!A:B,2,0)&"-"&VLOOKUP(Table4[[#This Row],[Category]],'Mapping code'!E:F,2,0)&"-"&VLOOKUP(Table4[[#This Row],[Machine]],'Mapping code'!I:J,2,0)&"-"&VLOOKUP(Table4[[#This Row],[Product Nature]],'Mapping code'!N:O,2,0)&"-"&VLOOKUP(Table4[[#This Row],[Category2]],'Mapping code'!Q:R,2,0)&"-"&Table4[[#This Row],[Seq]] -> #N/A | O108: =+LEN(Table4[[#This Row],[New Item Code]]) -> #N/A | P108: MP0100 | Q108: Spare parts | S108: Spare parts ABB | T108: ABB
A109: ALV-0001 | B109: OW46719 | C109: Normal Spares-NS | D109: 130 | E109: No | F109: 1 | G109: =Table4[[#This Row],[Item Cost]]*Table4[[#This Row],[In Stock]] -> 130 | H109: Spare Parts | I109: Normal Spares | J109: Saw | K109: Common | L109: Common | M109: =IF(LEN(COUNTIFS($H$1:H109,$H109,$I$1:I109,$I109,$J$1:J109,$J109,$K$1:K109,K109,$L$1:L109,L109))=1,"00"&COUNTIFS($H$1:H109,$H109,$I$1:I109,$I109,$J$1:J109,$J109,$K$1:K109,K109,$L$1:L109,L109),IF(LEN(COUNTIFS($H$1:H109,$H109,$I$1:I109,$I109,$J$1:J109,$J109,$K$1:K109,K109,$L$1:L109,L109))=2,"0"&COUNTIFS($H$1:H109,$H109,$I$1:I109,$I109,$J$1:J109,$J109,$K$1:K109,K109,$L$1:L109,L109),COUNTIFS($H$1:H109,$H109,$I$1:I109,$I109,$J$1:J109,$J109,$K$1:K109,K109,$L$1:L109,L109))) -> 001 | N109: =VLOOKUP(Table4[[#This Row],[Department]],'Mapping code'!A:B,2,0)&"-"&VLOOKUP(Table4[[#This Row],[Category]],'Mapping code'!E:F,2,0)&"-"&VLOOKUP(Table4[[#This Row],[Machine]],'Mapping code'!I:J,2,0)&"-"&VLOOKUP(Table4[[#This Row],[Product Nature]],'Mapping code'!N:O,2,0)&"-"&VLOOKUP(Table4[[#This Row],[Category2]],'Mapping code'!Q:R,2,0)&"-"&Table4[[#This Row],[Seq]] -> #N/A | O109: =+LEN(Table4[[#This Row],[New Item Code]]) -> #N/A | P109: MP0100 | Q109: Spare parts | T109: Saw
A110: ALV-0002 | B110: OW46718 | C110: Normal Spares-NS | D110: 130 | E110: No | F110: 1 | G110: =Table4[[#This Row],[Item Cost]]*Table4[[#This Row],[In Stock]] -> 130 | H110: Spare Parts | I110: Normal Spares | J110: Saw | K110: Common | L110: Common | M110: =IF(LEN(COUNTIFS($H$1:H110,$H110,$I$1:I110,$I110,$J$1:J110,$J110,$K$1:K110,K110,$L$1:L110,L110))=1,"00"&COUNTIFS($H$1:H110,$H110,$I$1:I110,$I110,$J$1:J110,$J110,$K$1:K110,K110,$L$1:L110,L110),IF(LEN(COUNTIFS($H$1:H110,$H110,$I$1:I110,$I110,$J$1:J110,$J110,$K$1:K110,K110,$L$1:L110,L110))=2,"0"&COUNTIFS($H$1:H110,$H110,$I$1:I110,$I110,$J$1:J110,$J110,$K$1:K110,K110,$L$1:L110,L110),COUNTIFS($H$1:H110,$H110,$I$1:I110,$I110,$J$1:J110,$J110,$K$1:K110,K110,$L$1:L110,L110))) -> 002 | N110: =VLOOKUP(Table4[[#This Row],[Department]],'Mapping code'!A:B,2,0)&"-"&VLOOKUP(Table4[[#This Row],[Category]],'Mapping code'!E:F,2,0)&"-"&VLOOKUP(Table4[[#This Row],[Machine]],'Mapping code'!I:J,2,0)&"-"&VLOOKUP(Table4[[#This Row],[Product Nature]],'Mapping code'!N:O,2,0)&"-"&VLOOKUP(Table4[[#This Row],[Category2]],'Mapping code'!Q:R,2,0)&"-"&Table4[[#This Row],[Seq]] -> #N/A | O110: =+LEN(Table4[[#This Row],[New Item Code]]) -> #N/A | P110: MP0100 | Q110: Spare parts | T110: Saw
A111: ALV-0003 | B111: CLAMPING CYLINDER | C111: Normal Spares-NS | D111: 1100 | E111: No | F111: 0 | G111: =Table4[[#This Row],[Item Cost]]*Table4[[#This Row],[In Stock]] -> 0 | H111: Spare Parts | I111: Normal Spares | J111: Saw | K111: Common | L111: Common | M111: =IF(LEN(COUNTIFS($H$1:H111,$H111,$I$1:I111,$I111,$J$1:J111,$J111,$K$1:K111,K111,$L$1:L111,L111))=1,"00"&COUNTIFS($H$1:H111,$H111,$I$1:I111,$I111,$J$1:J111,$J111,$K$1:K111,K111,$L$1:L111,L111),IF(LEN(COUNTIFS($H$1:H111,$H111,$I$1:I111,$I111,$J$1:J111,$J111,$K$1:K111,K111,$L$1:L111,L111))=2,"0"&COUNTIFS($H$1:H111,$H111,$I$1:I111,$I111,$J$1:J111,$J111,$K$1:K111,K111,$L$1:L111,L111),COUNTIFS($H$1:H111,$H111,$I$1:I111,$I111,$J$1:J111,$J111,$K$1:K111,K111,$L$1:L111,L111))) -> 003 | N111: =VLOOKUP(Table4[[#This Row],[Department]],'Mapping code'!A:B,2,0)&"-"&VLOOKUP(Table4[[#This Row],[Category]],'Mapping code'!E:F,2,0)&"-"&VLOOKUP(Table4[[#This Row],[Machine]],'Mapping code'!I:J,2,0)&"-"&VLOOKUP(Table4[[#This Row],[Product Nature]],'Mapping code'!N:O,2,0)&"-"&VLOOKUP(Table4[[#This Row],[Category2]],'Mapping code'!Q:R,2,0)&"-"&Table4[[#This Row],[Seq]] -> #N/A | O111: =+LEN(Table4[[#This Row],[New Item Code]]) -> #N/A | P111: MP0100 | Q111: Spare parts | T111: Saw
A112: ALV-0004 | B112: 60308158 | C112: Normal Spares-NS | D112: 350 | E112: No | F112: 0 | G112: =Table4[[#This Row],[Item Cost]]*Table4[[#This Row],[In Stock]] -> 0 | H112: Spare Parts | I112: Normal Spares | J112: Saw | K112: Common | L112: Common | M112: =IF(LEN(COUNTIFS($H$1:H112,$H112,$I$1:I112,$I112,$J$1:J112,$J112,$K$1:K112,K112,$L$1:L112,L112))=1,"00"&COUNTIFS($H$1:H112,$H112,$I$1:I112,$I112,$J$1:J112,$J112,$K$1:K112,K112,$L$1:L112,L112),IF(LEN(COUNTIFS($H$1:H112,$H112,$I$1:I112,$I112,$J$1:J112,$J112,$K$1:K112,K112,$L$1:L112,L112))=2,"0"&COUNTIFS($H$1:H112,$H112,$I$1:I112,$I112,$J$1:J112,$J112,$K$1:K112,K112,$L$1:L112,L112),COUNTIFS($H$1:H112,$H112,$I$1:I112,$I112,$J$1:J112,$J112,$K$1:K112,K112,$L$1:L112,L112))) -> 004 | N112: =VLOOKUP(Table4[[#This Row],[Department]],'Mapping code'!A:B,2,0)&"-"&VLOOKUP(Table4[[#This Row],[Category]],'Mapping code'!E:F,2,0)&"-"&VLOOKUP(Table4[[#This Row],[Machine]],'Mapping code'!I:J,2,0)&"-"&VLOOKUP(Table4[[#This Row],[Product Nature]],'Mapping code'!N:O,2,0)&"-"&VLOOKUP(Table4[[#This Row],[Category2]],'Mapping code'!Q:R,2,0)&"-"&Table4[[#This Row],[Seq]] -> #N/A | O112: =+LEN(Table4[[#This Row],[New Item Code]]) -> #N/A | P112: MP0100 | Q112: Spare parts | T112: Saw
A113: ALV-0005 | B113: HOOD STRIPS | C113: Normal Spares-NS | D113: 2400 | E113: No | F113: 0 | G113: =Table4[[#This Row],[Item Cost]]*Table4[[#This Row],[In Stock]] -> 0 | H113: Spare Parts | I113: Normal Spares | J113: Saw | K113: Common | L113: Common | M113: =IF(LEN(COUNTIFS($H$1:H113,$H113,$I$1:I113,$I113,$J$1:J113,$J113,$K$1:K113,K113,$L$1:L113,L113))=1,"00"&COUNTIFS($H$1:H113,$H113,$I$1:I113,$I113,$J$1:J113,$J113,$K$1:K113,K113,$L$1:L113,L113),IF(LEN(COUNTIFS($H$1:H113,$H113,$I$1:I113,$I113,$J$1:J113,$J113,$K$1:K113,K113,$L$1:L113,L113))=2,"0"&COUNTIFS($H$1:H113,$H113,$I$1:I113,$I113,$J$1:J113,$J113,$K$1:K113,K113,$L$1:L113,L113),COUNTIFS($H$1:H113,$H113,$I$1:I113,$I113,$J$1:J113,$J113,$K$1:K113,K113,$L$1:L113,L113))) -> 005 | N113: =VLOOKUP(Table4[[#This Row],[Department]],'Mapping code'!A:B,2,0)&"-"&VLOOKUP(Table4[[#This Row],[Category]],'Mapping code'!E:F,2,0)&"-"&VLOOKUP(Table4[[#This Row],[Machine]],'Mapping code'!I:J,2,0)&"-"&VLOOKUP(Table4[[#This Row],[Product Nature]],'Mapping code'!N:O,2,0)&"-"&VLOOKUP(Table4[[#This Row],[Category2]],'Mapping code'!Q:R,2,0)&"-"&Table4[[#This Row],[Seq]] -> #N/A | O113: =+LEN(Table4[[#This Row],[New Item Code]]) -> #N/A | P113: MP0100 | Q113: Spare parts | T113: Saw
A114: ALV-0006 | B114: LIMIT SWITCH FM 515-M2 | C114: Normal Spares-NS | D114: 350 | E114: No | F114: 0 | G114: =Table4[[#This Row],[Item Cost]]*Table4[[#This Row],[In Stock]] -> 0 | H114: Spare Parts | I114: Normal Spares | J114: Saw | K114: Common | L114: Common | M114: =IF(LEN(COUNTIFS($H$1:H114,$H114,$I$1:I114,$I114,$J$1:J114,$J114,$K$1:K114,K114,$L$1:L114,L114))=1,"00"&COUNTIFS($H$1:H114,$H114,$I$1:I114,$I114,$J$1:J114,$J114,$K$1:K114,K114,$L$1:L114,L114),IF(LEN(COUNTIFS($H$1:H114,$H114,$I$1:I114,$I114,$J$1:J114,$J114,$K$1:K114,K114,$L$1:L114,L114))=2,"0"&COUNTIFS($H$1:H114,$H114,$I$1:I114,$I114,$J$1:J114,$J114,$K$1:K114,K114,$L$1:L114,L114),COUNTIFS($H$1:H114,$H114,$I$1:I114,$I114,$J$1:J114,$J114,$K$1:K114,K114,$L$1:L114,L114))) -> 006 | N114: =VLOOKUP(Table4[[#This Row],[Department]],'Mapping code'!A:B,2,0)&"-"&VLOOKUP(Table4[[#This Row],[Category]],'Mapping code'!E:F,2,0)&"-"&VLOOKUP(Table4[[#This Row],[Machine]],'Mapping code'!I:J,2,0)&"-"&VLOOKUP(Table4[[#This Row],[Product Nature]],'Mapping code'!N:O,2,0)&"-"&VLOOKUP(Table4[[#This Row],[Category2]],'Mapping code'!Q:R,2,0)&"-"&Table4[[#This Row],[Seq]] -> #N/A | O114: =+LEN(Table4[[#This Row],[New Item Code]]) -> #N/A | P114: MP0100 | Q114: Spare parts | T114: Saw
A115: ALV-0007 | B115: BREAKER AA74393 | C115: Normal Spares-NS | D115: 850 | E115: No | F115: 0 | G115: =Table4[[#This Row],[Item Cost]]*Table4[[#This Row],[In Stock]] -> 0 | H115: Spare Parts | I115: Normal Spares | J115: Saw | K115: Common | L115: Common | M115: =IF(LEN(COUNTIFS($H$1:H115,$H115,$I$1:I115,$I115,$J$1:J115,$J115,$K$1:K115,K115,$L$1:L115,L115))=1,"00"&COUNTIFS($H$1:H115,$H115,$I$1:I115,$I115,$J$1:J115,$J115,$K$1:K115,K115,$L$1:L115,L115),IF(LEN(COUNTIFS($H$1:H115,$H115,$I$1:I115,$I115,$J$1:J115,$J115,$K$1:K115,K115,$L$1:L115,L115))=2,"0"&COUNTIFS($H$1:H115,$H115,$I$1:I115,$I115,$J$1:J115,$J115,$K$1:K115,K115,$L$1:L115,L115),COUNTIFS($H$1:H115,$H115,$I$1:I115,$I115,$J$1:J115,$J115,$K$1:K115,K115,$L$1:L115,L115))) -> 007 | N115: =VLOOKUP(Table4[[#This Row],[Department]],'Mapping code'!A:B,2,0)&"-"&VLOOKUP(Table4[[#This Row],[Category]],'Mapping code'!E:F,2,0)&"-"&VLOOKUP(Table4[[#This Row],[Machine]],'Mapping code'!I:J,2,0)&"-"&VLOOKUP(Table4[[#This Row],[Product Nature]],'Mapping code'!N:O,2,0)&"-"&VLOOKUP(Table4[[#This Row],[Category2]],'Mapping code'!Q:R,2,0)&"-"&Table4[[#This Row],[Seq]] -> #N/A | O115: =+LEN(Table4[[#This Row],[New Item Code]]) -> #N/A | P115: MP0100 | Q115: Spare parts | T115: Saw
A116: ALV-0008 | B116: FITTINGS REGULATOR BT 711975 | C116: Normal Spares-NS | D116: 350 | E116: No | F116: 1 | G116: =Table4[[#This Row],[Item Cost]]*Table4[[#This Row],[In Stock]] -> 350 | H116: Spare Parts | I116: Normal Spares | J116: Saw | K116: Common | L116: Common | M116: =IF(LEN(COUNTIFS($H$1:H116,$H116,$I$1:I116,$I116,$J$1:J116,$J116,$K$1:K116,K116,$L$1:L116,L116))=1,"00"&COUNTIFS($H$1:H116,$H116,$I$1:I116,$I116,$J$1:J116,$J116,$K$1:K116,K116,$L$1:L116,L116),IF(LEN(COUNTIFS($H$1:H116,$H116,$I$1:I116,$I116,$J$1:J116,$J116,$K$1:K116,K116,$L$1:L116,L116))=2,"0"&COUNTIFS($H$1:H116,$H116,$I$1:I116,$I116,$J$1:J116,$J116,$K$1:K116,K116,$L$1:L116,L116),COUNTIFS($H$1:H116,$H116,$I$1:I116,$I116,$J$1:J116,$J116,$K$1:K116,K116,$L$1:L116,L116))) -> 008 | N116: =VLOOKUP(Table4[[#This Row],[Department]],'Mapping code'!A:B,2,0)&"-"&VLOOKUP(Table4[[#This Row],[Category]],'Mapping code'!E:F,2,0)&"-"&VLOOKUP(Table4[[#This Row],[Machine]],'Mapping code'!I:J,2,0)&"-"&VLOOKUP(Table4[[#This Row],[Product Nature]],'Mapping code'!N:O,2,0)&"-"&VLOOKUP(Table4[[#This Row],[Category2]],'Mapping code'!Q:R,2,0)&"-"&Table4[[#This Row],[Seq]] -> #N/A | O116: =+LEN(Table4[[#This Row],[New Item Code]]) -> #N/A | P116: MP0100 | Q116: Spare parts | T116: Saw
A117: ALV-0009 | B117: FITTINGS REGULATOR BT 711974 | C117: Normal Spares-NS | D117: 350 | E117: No | F117: 1 | G117: =Table4[[#This Row],[Item Cost]]*Table4[[#This Row],[In Stock]] -> 350 | H117: Spare Parts | I117: Normal Spares | J117: Saw | K117: Common | L117: Common | M117: =IF(LEN(COUNTIFS($H$1:H117,$H117,$I$1:I117,$I117,$J$1:J117,$J117,$K$1:K117,K117,$L$1:L117,L117))=1,"00"&COUNTIFS($H$1:H117,$H117,$I$1:I117,$I117,$J$1:J117,$J117,$K$1:K117,K117,$L$1:L117,L117),IF(LEN(COUNTIFS($H$1:H117,$H117,$I$1:I117,$I117,$J$1:J117,$J117,$K$1:K117,K117,$L$1:L117,L117))=2,"0"&COUNTIFS($H$1:H117,$H117,$I$1:I117,$I117,$J$1:J117,$J117,$K$1:K117,K117,$L$1:L117,L117),COUNTIFS($H$1:H117,$H117,$I$1:I117,$I117,$J$1:J117,$J117,$K$1:K117,K117,$L$1:L117,L117))) -> 009 | N117: =VLOOKUP(Table4[[#This Row],[Department]],'Mapping code'!A:B,2,0)&"-"&VLOOKUP(Table4[[#This Row],[Category]],'Mapping code'!E:F,2,0)&"-"&VLOOKUP(Table4[[#This Row],[Machine]],'Mapping code'!I:J,2,0)&"-"&VLOOKUP(Table4[[#This Row],[Product Nature]],'Mapping code'!N:O,2,0)&"-"&VLOOKUP(Table4[[#This Row],[Category2]],'Mapping code'!Q:R,2,0)&"-"&Table4[[#This Row],[Seq]] -> #N/A | O117: =+LEN(Table4[[#This Row],[New Item Code]]) -> #N/A | P117: MP0100 | Q117: Spare parts | T117: Saw
A118: ALV-0010 | B118: BREAKER AA74142 | C118: Normal Spares-NS | D118: 250 | E118: No | F118: 0 | G118: =Table4[[#This Row],[Item Cost]]*Table4[[#This Row],[In Stock]] -> 0 | H118: Spare Parts | I118: Normal Spares | J118: Saw | K118: Common | L118: Common | M118: =IF(LEN(COUNTIFS($H$1:H118,$H118,$I$1:I118,$I118,$J$1:J118,$J118,$K$1:K118,K118,$L$1:L118,L118))=1,"00"&COUNTIFS($H$1:H118,$H118,$I$1:I118,$I118,$J$1:J118,$J118,$K$1:K118,K118,$L$1:L118,L118),IF(LEN(COUNTIFS($H$1:H118,$H118,$I$1:I118,$I118,$J$1:J118,$J118,$K$1:K118,K118,$L$1:L118,L118))=2,"0"&COUNTIFS($H$1:H118,$H118,$I$1:I118,$I118,$J$1:J118,$J118,$K$1:K118,K118,$L$1:L118,L118),COUNTIFS($H$1:H118,$H118,$I$1:I118,$I118,$J$1:J118,$J118,$K$1:K118,K118,$L$1:L118,L118))) -> 010 | N118: =VLOOKUP(Table4[[#This Row],[Department]],'Mapping code'!A:B,2,0)&"-"&VLOOKUP(Table4[[#This Row],[Category]],'Mapping code'!E:F,2,0)&"-"&VLOOKUP(Table4[[#This Row],[Machine]],'Mapping code'!I:J,2,0)&"-"&VLOOKUP(Table4[[#This Row],[Product Nature]],'Mapping code'!N:O,2,0)&"-"&VLOOKUP(Table4[[#This Row],[Category2]],'Mapping code'!Q:R,2,0)&"-"&Table4[[#This Row],[Seq]] -> #N/A | O118: =+LEN(Table4[[#This Row],[New Item Code]]) -> #N/A | P118: MP0100 | Q118: Spare parts | T118: Saw
A119: ALV-0011 | B119: HEAD MOTOR BK29146 | C119: Normal Spares-NS | D119: 6500 | E119: No | F119: 1 | G119: =Table4[[#This Row],[Item Cost]]*Table4[[#This Row],[In Stock]] -> 6500 | H119: Spare Parts | I119: Normal Spares | J119: Saw | K119: Common | L119: Common | M119: =IF(LEN(COUNTIFS($H$1:H119,$H119,$I$1:I119,$I119,$J$1:J119,$J119,$K$1:K119,K119,$L$1:L119,L119))=1,"00"&COUNTIFS($H$1:H119,$H119,$I$1:I119,$I119,$J$1:J119,$J119,$K$1:K119,K119,$L$1:L119,L119),IF(LEN(COUNTIFS($H$1:H119,$H119,$I$1:I119,$I119,$J$1:J119,$J119,$K$1:K119,K119,$L$1:L119,L119))=2,"0"&COUNTIFS($H$1:H119,$H119,$I$1:I119,$I119,$J$1:J119,$J119,$K$1:K119,K119,$L$1:L119,L119),COUNTIFS($H$1:H119,$H119,$I$1:I119,$I119,$J$1:J119,$J119,$K$1:K119,K119,$L$1:L119,L119))) -> 011 | N119: =VLOOKUP(Table4[[#This Row],[Department]],'Mapping code'!A:B,2,0)&"-"&VLOOKUP(Table4[[#This Row],[Category]],'Mapping code'!E:F,2,0)&"-"&VLOOKUP(Table4[[#This Row],[Machine]],'Mapping code'!I:J,2,0)&"-"&VLOOKUP(Table4[[#This Row],[Product Nature]],'Mapping code'!N:O,2,0)&"-"&VLOOKUP(Table4[[#This Row],[Category2]],'Mapping code'!Q:R,2,0)&"-"&Table4[[#This Row],[Seq]] -> #N/A | O119: =+LEN(Table4[[#This Row],[New Item Code]]) -> #N/A | P119: MP0100 | Q119: Spare parts | T119: Saw
A120: ALV-0012 | B120: BLADE UNIT BK28869 | C120: Normal Spares-NS | D120: 850 | E120: No | F120: 1 | G120: =Table4[[#This Row],[Item Cost]]*Table4[[#This Row],[In Stock]] -> 850 | H120: Spare Parts | I120: Normal Spares | J120: Saw | K120: Common | L120: Common | M120: =IF(LEN(COUNTIFS($H$1:H120,$H120,$I$1:I120,$I120,$J$1:J120,$J120,$K$1:K120,K120,$L$1:L120,L120))=1,"00"&COUNTIFS($H$1:H120,$H120,$I$1:I120,$I120,$J$1:J120,$J120,$K$1:K120,K120,$L$1:L120,L120),IF(LEN(COUNTIFS($H$1:H120,$H120,$I$1:I120,$I120,$J$1:J120,$J120,$K$1:K120,K120,$L$1:L120,L120))=2,"0"&COUNTIFS($H$1:H120,$H120,$I$1:I120,$I120,$J$1:J120,$J120,$K$1:K120,K120,$L$1:L120,L120),COUNTIFS($H$1:H120,$H120,$I$1:I120,$I120,$J$1:J120,$J120,$K$1:K120,K120,$L$1:L120,L120))) -> 012 | N120: =VLOOKUP(Table4[[#This Row],[Department]],'Mapping code'!A:B,2,0)&"-"&VLOOKUP(Table4[[#This Row],[Category]],'Mapping code'!E:F,2,0)&"-"&VLOOKUP(Table4[[#This Row],[Machine]],'Mapping code'!I:J,2,0)&"-"&VLOOKUP(Table4[[#This Row],[Product Nature]],'Mapping code'!N:O,2,0)&"-"&VLOOKUP(Table4[[#This Row],[Category2]],'Mapping code'!Q:R,2,0)&"-"&Table4[[#This Row],[Seq]] -> #N/A | O120: =+LEN(Table4[[#This Row],[New Item Code]]) -> #N/A | P120: MP0100 | Q120: Spare parts | T120: Saw
...

Sheet Mapping code
A1: Description | B1: Type | E1: Type | F1: Coding | I1: Type | J1: Coding | N1: Product Nature | O1: Coding | Q1: Category | R1: Coding
A2: Maintenance Section | B2: MS | E2: Critical Spares | F2: CS | I2: Common | J2: 000 | N2: Common | O2: 00 | Q2: Common | R2: 00
A3: KTL Section | B3: KS | E3: Normal Spares | F3: NS | I3: Dugard | J3: 001 | N3: Drive | O3: 01 | Q3: FSFCM/ FSRCM | R3: 01
A4: Engineering Section | B4: ES | I4: Emmegi | J4: 002 | N4: Spindle | O4: 02 | Q4: Frunk Beam | R4: 02
A5: Industrialization Section | B5: IS | I5: Ralc | J5: 003 | N5: Axis | O5: 03 | Q5: L-track | R5: 03
A6: Production Section | B6: PS | I6: ABB | J6: 004 | N6: Cylinder | O6: 04 | Q6: Tube Ex | R6: 04
A7: Facility Section | B7: FS | I7: Saw | J7: 005 | N7: Belt | O7: 05 | Q7: F39 | R7: 05
A8: Quality Section | B8: QS | I8: Bender | J8: 006 | N8: Motor | O8: 06 | Q8: XFB | R8: 06
I9: Drill | J9: 007 | N9: Pump | O9: 07 | Q9: Jeep | R9: 07
I10: Air Compressor | J10: 008 | N10: Clamp | O10: 08 | Q10: VS 20 | R10: 08
I11: Crimping | J11: 009 | N11: Switch | O11: 09 | Q11: L462 | R11: 09
I12: Desoutter | J12: 010 | N12: Valve | O12: 10 | Q12: L538 | R12: 10
I13: Fixtures | J13: 011 | N13: Relay | O13: 11 | Q13: VS 20 | R13: 11
I14: Electrical components | J14: 012 | N14: Stopper | O14: 12 | Q14: Gestamp | R14: 12
I15: Exechon | J15: 013 | N15: Cable | O15: 13 | Q15: B479 | R15: 13
I16: FSM | J16: 014 | N16: Enclosure | O16: 14 | Q16: Centre Ski | R16: 14
I17: Floor Scrubber | J17: 015 | N17: Safety Light barrier | O17: 15 | Q17: Mega Pack | R17: 15
I18: Laser Mark | J18: 016 | N18: Safety module | O18: 16 | Q18: NE 42 | R18: 16
I19: Haco | J19: 017 | N19: Air fittings | O19: 17 | Q19: Ceer | R19: 17
I20: Assembly | J20: 018 | N20: Hydraulic components | O20: 18 | Q20: Daimler | R20: 18
I21: Mecal | J21: 019 | N21: Pulley | O21: 19
I22: Nortech | J22: 020 | N22: Accumulator | O22: 20
I23: Oven | J23: 021 | N23: Nuts and bolts | O23: 21
I24: Permsetter | J24: 022 | N24: Bearings | O24: 22
I25: Pneumatic | J25: 023 | N25: Electrical components | O25: 23
I26: Press | J26: 024 | N26: O'rings and seals | O26: 24
I27: STA | J27: 025 | N27: Pipes | O27: 25
I28: Tap and Drill | J28: 026 | N28: Mechanical components | O28: 26
I29: Thread Check | J29: 027 | N29: Safety interlock | O29: 27
I30: Wensing | J30: 028 | N30: Repair kit | O30: 28
I31: 4head saw | J31: 029 | N31: Fixtures blocks | O31: 29
I32: Tox | J32: 030 | N32: Pneumatic components | O32: 30
... I36: Steam | J36: 034 | N36: Blades | O36: 34

Sheet Search II codes
A1: Code | B1: Description
A2: ABB | B2: Abb milling cells
A3: ABBFX | B3: Abb milling cells fixture
A4: BEA | B4: Bearings
A5: BEN | B5: Benders
A6: CBO | B6: counter bore machine
A7: COM | B7: Compressor
A8: CTE | B8: Crimping tube extrusion
A9: DRS | B9: Desrouters
A10: DUG | B10: Dugard
A11: EGF | B11: Emmegi Gestamp fixtures
A12: ELE | B12: electrical components
... A45: YIL | B45: 4 head saw

Sheet Centralized store items
A1: Search I code | B1: New Item Description | C1: New Item Group | D1: Item Cost | E1: New Inventory | F1: Min | G1: Max | H1: In Stock | I1: Total Cost | J1: Department | K1: Category | L1: Machine | M1: Product Nature | N1: Category2 | O1: Seq | P1: New Item Code | Q1: Store Location | R1: Column1 | S1: Column2 | T1: Invnetory in Qty | U1: Invnetory in Value | V1: Stock Count February
A2: ABB-0001 | B2: Package wires on the robot - signal 25463 - ROBOFLEX 2001 12G0,5 QMM 300/500V | C2: Critical Spares-CS | D2: 84.214 | E2: Yes | F2: 1 | G2: 3 | H2: 20 | I2: =Table43[[#This Row],[Item Cost]]*Table43[[#This Row],[In Stock]] -> 1684.28 | J2: Maintenance Section | K2: Critical Spares | L2: ABB | M2: Cable | N2: FSFCM/ FSRCM | O2: =IF(LEN(COUNTIFS($J$1:J2,$J2,$K$1:K2,$K2,$L$1:L2,$L2,$M$1:M2,M2,$N$1:N2,N2))=1,"00"&COUNTIFS($J$1:J2,$J2,$K$1:K2,$K2,$L$1:L2,$L2,$M$1:M2,M2,$N$1:N2,N2),IF(LEN(COUNTIFS($J$1:J2,$J2,$K$1:K2,$K2,$L$1:L2,$L2,$M$1:M2,M2,$N$1:N2,N2))=2,"0"&COUNTIFS($J$1:J2,$J2,$K$1:K2,$K2,$L$1:L2,$L2,$M$1:M2,M2,$N$1:N2,N2),COUNTIFS($J$1:J2,$J2,$K$1:K2,$K2,$L$1:L2,$L2,$M$1:M2,M2,$N$1:N2,N2))) -> 001 | P2: =VLOOKUP(Table43[[#This Row],[Department]],'Mapping code'!A:B,2,0)&"-"&VLOOKUP(Table43[[#This Row],[Category]],'Mapping code'!E:F,2,0)&"-"&VLOOKUP(Table43[[#This Row],[Machine]],'Mapping code'!I:J,2,0)&"-"&VLOOKUP(Table43[[#This Row],[Product Nature]],'Mapping code'!N:O,2,0)&"-"&VLOOKUP(Table43[[#This Row],[Category2]],'Mapping code'!Q:R,2,0)&Table43[[#This Row],[Seq]]&IF(Table43[[#This Row],[New Inventory]]="Yes","-INV","") -> MS-CS-004-13-01001-INV | R2: MP-CS-004-00-00001 | S2: Package wires on the robot - signal 25463 - ROBOFLEX 2001 12 | T2: =+IFERROR(_xlfn.XLOOKUP(Table43[[#This Row],[Column1]],#REF!,#REF!),0) -> 0 | U2: =IFERROR(_xlfn.XLOOKUP(Table43[[#This Row],[Column1]],#REF!,#REF!),0) -> 0
A3: ABB-0002 | B3: Package wires on the robot - power supply 29692 - ÖLFLEX® ROBOT F1 ( C ) 4 G 2,5 + (2 x 1,0 | C3: Critical Spares-CS | D3: 76.194 | E3: Yes | F3: 1 | G3: 3 | H3: 20 | I3: =Table43[[#This Row],[Item Cost]]*Table43[[#This Row],[In Stock]] -> 1523.88 | J3: Maintenance Section | K3: Critical Spares | L3: ABB | M3: Cable | N3: FSFCM/ FSRCM | O3: =IF(LEN(COUNTIFS($J$1:J3,$J3,$K$1:K3,$K3,$L$1:L3,$L3,$M$1:M3,M3,$N$1:N3,N3))=1,"00"&COUNTIFS($J$1:J3,$J3,$K$1:K3,$K3,$L$1:L3,$L3,$M$1:M3,M3,$N$1:N3,N3),IF(LEN(COUNTIFS($J$1:J3,$J3,$K$1:K3,$K3,$L$1:L3,$L3,$M$1:M3,M3,$N$1:N3,N3))=2,"0"&COUNTIFS($J$1:J3,$J3,$K$1:K3,$K3,$L$1:L3,$L3,$M$1:M3,M3,$N$1:N3,N3),COUNTIFS($J$1:J3,$J3,$K$1:K3,$K3,$L$1:L3,$L3,$M$1:M3,M3,$N$1:N3,N3))) -> 002 | P3: =VLOOKUP(Table43[[#This Row],[Department]],'Mapping code'!A:B,2,0)&"-"&VLOOKUP(Table43[[#This Row],[Category]],'Mapping code'!E:F,2,0)&"-"&VLOOKUP(Table43[[#This Row],[Machine]],'Mapping code'!I:J,2,0)&"-"&VLOOKUP(Table43[[#This Row],[Product Nature]],'Mapping code'!N:O,2,0)&"-"&VLOOKUP(Table43[[#This Row],[Category2]],'Mapping code'!Q:R,2,0)&Table43[[#This Row],[Seq]]&IF(Table43[[#This Row],[New Inventory]]="Yes","-INV","") -> MS-CS-004-13-01002-INV | R3: MP-CS-004-00-00002 | S3: Package wires on the robot - power supply 29692 - ÖLFLEX® RO | T3: =+IFERROR(_xlfn.XLOOKUP(Table43[[#This Row],[Column1]],#REF!,#REF!),0) -> 0 | U3: =IFERROR(_xlfn.XLOOKUP(Table43[[#This Row],[Column1]],#REF!,#REF!),0) -> 0
A4: ABB-0003 | B4: Electrospindle ES350L - H6161H0485 - New | C4: Critical Spares-CS | D4: 33284.66 | E4: Yes | F4: 1 | G4: 3 | H4: 1 | I4: =Table43[[#This Row],[Item Cost]]*Table43[[#This Row],[In Stock]] -> 33284.66 | J4: Maintenance Section | K4: Critical Spares | L4: ABB | M4: Spindle | N4: FSFCM/ FSRCM | O4: =IF(LEN(COUNTIFS($J$1:J4,$J4,$K$1:K4,$K4,$L$1:L4,$L4,$M$1:M4,M4,$N$1:N4,N4))=1,"00"&COUNTIFS($J$1:J4,$J4,$K$1:K4,$K4,$L$1:L4,$L4,$M$1:M4,M4,$N$1:N4,N4),IF(LEN(COUNTIFS($J$1:J4,$J4,$K$1:K4,$K4,$L$1:L4,$L4,$M$1:M4,M4,$N$1:N4,N4))=2,"0"&COUNTIFS($J$1:J4,$J4,$K$1:K4,$K4,$L$1:L4,$L4,$M$1:M4,M4,$N$1:N4,N4),COUNTIFS($J$1:J4,$J4,$K$1:K4,$K4,$L$1:L4,$L4,$M$1:M4,M4,$N$1:N4,N4))) -> 001 | P4: =VLOOKUP(Table43[[#This Row],[Department]],'Mapping code'!A:B,2,0)&"-"&VLOOKUP(Table43[[#This Row],[Category]],'Mapping code'!E:F,2,0)&"-"&VLOOKUP(Table43[[#This Row],[Machine]],'Mapping code'!I:J,2,0)&"-"&VLOOKUP(Table43[[#This Row],[Product Nature]],'Mapping code'!N:O,2,0)&"-"&VLOOKUP(Table43[[#This Row],[Category2]],'Mapping code'!Q:R,2,0)&Table43[[#This Row],[Seq]]&IF(Table43[[#This Row],[New Inventory]]="Yes","-INV","") -> MS-CS-004-02-01001-INV | R4: MP-CS-004-00-00003 | S4: Electrospindle ES350L - H6161H0485 - New | T4: =+IFERROR(_xlfn.XLOOKUP(Table43[[#This Row],[Column1]],#REF!,#REF!),0) -> 0 | U4: =IFERROR(_xlfn.XLOOKUP(Table43[[#This Row],[Column1]],#REF!,#REF!),0) -> 0
A5: ABB-0004 | B5: OMRON Resistance brake A1000-REV00K6050-IE | C5: Critical Spares-CS | D5: 200.51 | E5: Yes | F5: 1 | G5: 2 | H5: 1 | I5: =Table43[[#This Row],[Item Cost]]*Table43[[#This Row],[In Stock]] -> 200.51 | J5: Maintenance Section | K5: Critical Spares | L5: ABB | M5: Electrical components | N5: FSFCM/ FSRCM | O5: =IF(LEN(COUNTIFS($J$1:J5,$J5,$K$1:K5,$K5,$L$1:L5,$L5,$M$1:M5,M5,$N$1:N5,N5))=1,"00"&COUNTIFS($J$1:J5,$J5,$K$1:K5,$K5,$L$1:L5,$L5,$M$1:M5,M5,$N$1:N5,N5),IF(LEN(COUNTIFS($J$1:J5,$J5,$K$1:K5,$K5,$L$1:L5,$L5,$M$1:M5,M5,$N$1:N5,N5))=2,"0"&COUNTIFS($J$1:J5,$J5,$K$1:K5,$K5,$L$1:L5,$L5,$M$1:M5,M5,$N$1:N5,N5),COUNTIFS($J$1:J5,$J5,$K$1:K5,$K5,$L$1:L5,$L5,$M$1:M5,M5,$N$1:N5,N5))) -> 001 | P5: =VLOOKUP(Table43[[#This Row],[Department]],'Mapping code'!A:B,2,0)&"-"&VLOOKUP(Table43[[#This Row],[Category]],'Mapping code'!E:F,2,0)&"-"&VLOOKUP(Table43[[#This Row],[Machine]],'Mapping code'!I:J,2,0)&"-"&VLOOKUP(Table43[[#This Row],[Product Nature]],'Mapping code'!N:O,2,0)&"-"&VLOOKUP(Table43[[#This Row],[Category2]],'Mapping code'!Q:R,2,0)&Table43[[#This Row],[Seq]]&IF(Table43[[#This Row],[New Inventory]]="Yes","-INV","") -> MS-CS-004-23-01001-INV | Q5: ABB D | R5: MP-CS-004-00-00004 | S5: OMRON Resistance brake A1000-REV00K6050-IE | T5: =+IFERROR(_xlfn.XLOOKUP(Table43[[#This Row],[Column1]],#REF!,#REF!),0) -> 0 | U5: =IFERROR(_xlfn.XLOOKUP(Table43[[#This Row],[Column1]],#REF!,#REF!),0) -> 0
A6: ABB-0005 | B6: Pluto B20 v2 2TLA020070R4600 | C6: Critical Spares-CS | D6: 2726.94 | E6: Yes | F6: 1 | G6: 2 | H6: 1 | I6: =Table43[[#This Row],[Item Cost]]*Table43[[#This Row],[In Stock]] -> 2726.94 | J6: Maintenance Section | K6: Critical Spares | L6: ABB | M6: Safety module | N6: FSFCM/ FSRCM | O6: =IF(LEN(COUNTIFS($J$1:J6,$J6,$K$1:K6,$K6,$L$1:L6,$L6,$M$1:M6,M6,$N$1:N6,N6))=1,"00"&COUNTIFS($J$1:J6,$J6,$K$1:K6,$K6,$L$1:L6,$L6,$M$1:M6,M6,$N$1:N6,N6),IF(LEN(COUNTIFS($J$1:J6,$J6,$K$1:K6,$K6,$L$1:L6,$L6,$M$1:M6,M6,$N$1:N6,N6))=2,"0"&COUNTIFS($J$1:J6,$J6,$K$1:K6,$K6,$L$1:L6,$L6,$M$1:M6,M6,$N$1:N6,N6),COUNTIFS($J$1:J6,$J6,$K$1:K6,$K6,$L$1:L6,$L6,$M$1:M6,M6,$N$1:N6,N6))) -> 001 | P6: =VLOOKUP(Table43[[#This Row],[Department]],'Mapping code'!A:B,2,0)&"-"&VLOOKUP(Table43[[#This Row],[Category]],'Mapping code'!E:F,2,0)&"-"&VLOOKUP(Table43[[#This Row],[Machine]],'Mapping code'!I:J,2,0)&"-"&VLOOKUP(Table43[[#This Row],[Product Nature]],'Mapping code'!N:O,2,0)&"-"&VLOOKUP(Table43[[#This Row],[Category2]],'Mapping code'!Q:R,2,0)&Table43[[#This Row],[Seq]]&IF(Table43[[#This Row],[New Inventory]]="Yes","-INV","") -> MS-CS-004-16-01001-INV | Q6: ABB B | R6: MP-CS-004-00-00005 | S6: Pluto B20 v2 2TLA020070R4600 | T6: =+IFERROR(_xlfn.XLOOKUP(Table43[[#This Row],[Column1]],#REF!,#REF!),0) -> 0 | U6: =IFERROR(_xlfn.XLOOKUP(Table43[[#This Row],[Column1]],#REF!,#REF!),0) -> 0
A7: ABB-0006 | B7: Pluto B46 v2 2TLA020070R1700 | C7: Critical Spares-CS | D7: 5072.01 | E7: Yes | F7: 1 | G7: 2 | H7: 1 | I7: =Table43[[#This Row],[Item Cost]]*Table43[[#This Row],[In Stock]] -> 5072.01 | J7: Maintenance Section | K7: Critical Spares | L7: ABB | M7: Safety module | N7: FSFCM/ FSRCM | O7: =IF(LEN(COUNTIFS($J$1:J7,$J7,$K$1:K7,$K7,$L$1:L7,$L7,$M$1:M7,M7,$N$1:N7,N7))=1,"00"&COUNTIFS($J$1:J7,$J7,$K$1:K7,$K7,$L$1:L7,$L7,$M$1:M7,M7,$N$1:N7,N7),IF(LEN(COUNTIFS($J$1:J7,$J7,$K$1:K7,$K7,$L$1:L7,$L7,$M$1:M7,M7,$N$1:N7,N7))=2,"0"&COUNTIFS($J$1:J7,$J7,$K$1:K7,$K7,$L$1:L7,$L7,$M$1:M7,M7,$N$1:N7,N7),COUNTIFS($J$1:J7,$J7,$K$1:K7,$K7,$L$1:L7,$L7,$M$1:M7,M7,$N$1:N7,N7))) -> 002 | P7: =VLOOKUP(Table43[[#This Row],[Department]],'Mapping code'!A:B,2,0)&"-"&VLOOKUP(Table43[[#This Row],[Category]],'Mapping code'!E:F,2,0)&"-"&VLOOKUP(Table43[[#This Row],[Machine]],'Mapping code'!I:J,2,0)&"-"&VLOOKUP(Table43[[#This Row],[Product Nature]],'Mapping code'!N:O,2,0)&"-"&VLOOKUP(Table43[[#This Row],[Category2]],'Mapping code'!Q:R,2,0)&Table43[[#This Row],[Seq]]&IF(Table43[[#This Row],[New Inventory]]="Yes","-INV","") -> MS-CS-004-16-01002-INV | Q7: ABB B | R7: MP-CS-004-00-00006 | S7: Pluto B46 v2 2TLA020070R1700 | T7: =+IFERROR(_xlfn.XLOOKUP(Table43[[#This Row],[Column1]],#REF!,#REF!),0) -> 0 | U7: =IFERROR(_xlfn.XLOOKUP(Table43[[#This Row],[Column1]],#REF!,#REF!),0) -> 0
